---
title: Prova... Rileva... Finally (istruzione)
description: Informazioni su come usare la gestione delle eccezioni con Visual Basic istruzioni try/catch/finally.
ms.date: 12/07/2018
f1_keywords:
- vb.Try...Catch...Finally
- vb.when
- vb.Finally
- vb.Catch
- vb.Try
helpviewer_keywords:
- Try...Catch...Finally statements
- Try statement [Visual Basic]
- try-catch exception handling, Try...Catch...Finally statements
- error handling, while running code
- Try statement [Visual Basic], Try...Catch...Finally
- Finally keyword [Visual Basic], Try...Catch...Finally
- Catch statement [Visual Basic]
- When keyword [Visual Basic]
- Visual Basic code, handling errors while running
- structured exception handling, Try...Catch...Finally statements
ms.assetid: d6488026-ccb3-42b8-a810-0d97b9d6472b
ms.openlocfilehash: 22f1611786a3da512632b5b547b7ef141c8f65c6
ms.sourcegitcommit: f8c270376ed905f6a8896ce0fe25b4f4b38ff498
ms.translationtype: MT
ms.contentlocale: it-IT
ms.lasthandoff: 06/04/2020
ms.locfileid: "84391768"
---
# <a name="trycatchfinally-statement-visual-basic"></a><span data-ttu-id="4f0d4-103">Istruzione Try...Catch...Finally (Visual Basic)</span><span class="sxs-lookup"><span data-stu-id="4f0d4-103">Try...Catch...Finally Statement (Visual Basic)</span></span>

<span data-ttu-id="4f0d4-104">Consente di gestire alcuni o tutti i possibili errori che possono verificarsi in un blocco di codice specifico, mentre è ancora in esecuzione il codice.</span><span class="sxs-lookup"><span data-stu-id="4f0d4-104">Provides a way to handle some or all possible errors that may occur in a given block of code, while still running code.</span></span>

## <a name="syntax"></a><span data-ttu-id="4f0d4-105">Sintassi</span><span class="sxs-lookup"><span data-stu-id="4f0d4-105">Syntax</span></span>

```vb
Try
    [ tryStatements ]
    [ Exit Try ]
[ Catch [ exception [ As type ] ] [ When expression ]
    [ catchStatements ]
    [ Exit Try ] ]
[ Catch ... ]
[ Finally
    [ finallyStatements ] ]
End Try
```

## <a name="parts"></a><span data-ttu-id="4f0d4-106">Parti</span><span class="sxs-lookup"><span data-stu-id="4f0d4-106">Parts</span></span>

|<span data-ttu-id="4f0d4-107">Termine</span><span class="sxs-lookup"><span data-stu-id="4f0d4-107">Term</span></span>|<span data-ttu-id="4f0d4-108">Definizione</span><span class="sxs-lookup"><span data-stu-id="4f0d4-108">Definition</span></span>|
|---|---|
|`tryStatements`|<span data-ttu-id="4f0d4-109">Facoltativa.</span><span class="sxs-lookup"><span data-stu-id="4f0d4-109">Optional.</span></span> <span data-ttu-id="4f0d4-110">Istruzioni in cui può verificarsi un errore.</span><span class="sxs-lookup"><span data-stu-id="4f0d4-110">Statement(s) where an error can occur.</span></span> <span data-ttu-id="4f0d4-111">Può essere un'istruzione composta.</span><span class="sxs-lookup"><span data-stu-id="4f0d4-111">Can be a compound statement.</span></span>|
|`Catch`|<span data-ttu-id="4f0d4-112">Facoltativa.</span><span class="sxs-lookup"><span data-stu-id="4f0d4-112">Optional.</span></span> <span data-ttu-id="4f0d4-113">Sono `Catch` consentiti più blocchi.</span><span class="sxs-lookup"><span data-stu-id="4f0d4-113">Multiple `Catch` blocks permitted.</span></span> <span data-ttu-id="4f0d4-114">Se si verifica un'eccezione durante l'elaborazione del `Try` blocco, ogni `Catch` istruzione viene esaminata in ordine testuale per determinare se gestisce l'eccezione, con `exception` la rappresentazione dell'eccezione generata.</span><span class="sxs-lookup"><span data-stu-id="4f0d4-114">If an exception occurs when processing the `Try` block, each `Catch` statement is examined in textual order to determine whether it handles the exception, with `exception` representing the exception that has been thrown.</span></span>|
|`exception`|<span data-ttu-id="4f0d4-115">Facoltativa.</span><span class="sxs-lookup"><span data-stu-id="4f0d4-115">Optional.</span></span> <span data-ttu-id="4f0d4-116">Qualsiasi nome di variabile.</span><span class="sxs-lookup"><span data-stu-id="4f0d4-116">Any variable name.</span></span> <span data-ttu-id="4f0d4-117">Il valore iniziale di `exception` corrisponde al valore dell'errore generato.</span><span class="sxs-lookup"><span data-stu-id="4f0d4-117">The initial value of `exception` is the value of the thrown error.</span></span> <span data-ttu-id="4f0d4-118">Utilizzato con `Catch` per specificare l'errore rilevato.</span><span class="sxs-lookup"><span data-stu-id="4f0d4-118">Used with `Catch` to specify the error caught.</span></span> <span data-ttu-id="4f0d4-119">Se omesso, l' `Catch` istruzione rileva qualsiasi eccezione.</span><span class="sxs-lookup"><span data-stu-id="4f0d4-119">If omitted, the `Catch` statement catches any exception.</span></span>|
|`type`|<span data-ttu-id="4f0d4-120">Facoltativa.</span><span class="sxs-lookup"><span data-stu-id="4f0d4-120">Optional.</span></span> <span data-ttu-id="4f0d4-121">Specifica il tipo di filtro di classe.</span><span class="sxs-lookup"><span data-stu-id="4f0d4-121">Specifies the type of class filter.</span></span> <span data-ttu-id="4f0d4-122">Se il valore di `exception` è del tipo specificato da `type` o di un tipo derivato, l'identificatore viene associato all'oggetto Exception.</span><span class="sxs-lookup"><span data-stu-id="4f0d4-122">If the value of `exception` is of the type specified by `type` or of a derived type, the identifier becomes bound to the exception object.</span></span>|
|`When`|<span data-ttu-id="4f0d4-123">Facoltativa.</span><span class="sxs-lookup"><span data-stu-id="4f0d4-123">Optional.</span></span> <span data-ttu-id="4f0d4-124">Un' `Catch` istruzione con una `When` clausola intercetta le eccezioni solo quando `expression` restituisce `True` .</span><span class="sxs-lookup"><span data-stu-id="4f0d4-124">A `Catch` statement with a `When` clause catches exceptions only when `expression` evaluates to `True`.</span></span> <span data-ttu-id="4f0d4-125">Una `When` clausola viene applicata solo dopo avere verificato il tipo di eccezione e `expression` può fare riferimento all'identificatore che rappresenta l'eccezione.</span><span class="sxs-lookup"><span data-stu-id="4f0d4-125">A `When` clause is applied only after checking the type of the exception, and `expression` may refer to the identifier representing the exception.</span></span>|
|`expression`|<span data-ttu-id="4f0d4-126">Facoltativa.</span><span class="sxs-lookup"><span data-stu-id="4f0d4-126">Optional.</span></span> <span data-ttu-id="4f0d4-127">Deve essere convertibile in modo implicito in `Boolean` .</span><span class="sxs-lookup"><span data-stu-id="4f0d4-127">Must be implicitly convertible to `Boolean`.</span></span> <span data-ttu-id="4f0d4-128">Qualsiasi espressione che descrive un filtro generico.</span><span class="sxs-lookup"><span data-stu-id="4f0d4-128">Any expression that describes a generic filter.</span></span> <span data-ttu-id="4f0d4-129">Usato in genere per filtrare in base al numero di errore.</span><span class="sxs-lookup"><span data-stu-id="4f0d4-129">Typically used to filter by error number.</span></span> <span data-ttu-id="4f0d4-130">Usato con `When` la parola chiave per specificare le circostanze in cui viene rilevato l'errore.</span><span class="sxs-lookup"><span data-stu-id="4f0d4-130">Used with `When` keyword to specify circumstances under which the error is caught.</span></span>|
|`catchStatements`|<span data-ttu-id="4f0d4-131">Facoltativa.</span><span class="sxs-lookup"><span data-stu-id="4f0d4-131">Optional.</span></span> <span data-ttu-id="4f0d4-132">Istruzioni per gestire gli errori che si verificano nel blocco associato `Try` .</span><span class="sxs-lookup"><span data-stu-id="4f0d4-132">Statement(s) to handle errors that occur in the associated `Try` block.</span></span> <span data-ttu-id="4f0d4-133">Può essere un'istruzione composta.</span><span class="sxs-lookup"><span data-stu-id="4f0d4-133">Can be a compound statement.</span></span>|
|`Exit Try`|<span data-ttu-id="4f0d4-134">Facoltativa.</span><span class="sxs-lookup"><span data-stu-id="4f0d4-134">Optional.</span></span> <span data-ttu-id="4f0d4-135">Parola chiave che si interrompe dalla `Try...Catch...Finally` struttura.</span><span class="sxs-lookup"><span data-stu-id="4f0d4-135">Keyword that breaks out of the `Try...Catch...Finally` structure.</span></span> <span data-ttu-id="4f0d4-136">L'esecuzione riprende con il codice immediatamente successivo all' `End Try` istruzione.</span><span class="sxs-lookup"><span data-stu-id="4f0d4-136">Execution resumes with the code immediately following the `End Try` statement.</span></span> <span data-ttu-id="4f0d4-137">L' `Finally` istruzione verrà comunque eseguita.</span><span class="sxs-lookup"><span data-stu-id="4f0d4-137">The `Finally` statement will still be executed.</span></span> <span data-ttu-id="4f0d4-138">Non consentito nei `Finally` blocchi.</span><span class="sxs-lookup"><span data-stu-id="4f0d4-138">Not allowed in `Finally` blocks.</span></span>|
|`Finally`|<span data-ttu-id="4f0d4-139">Facoltativa.</span><span class="sxs-lookup"><span data-stu-id="4f0d4-139">Optional.</span></span> <span data-ttu-id="4f0d4-140">Un `Finally` blocco viene sempre eseguito quando l'esecuzione lascia una parte dell' `Try...Catch` istruzione.</span><span class="sxs-lookup"><span data-stu-id="4f0d4-140">A `Finally` block is always executed when execution leaves any part of the `Try...Catch` statement.</span></span>|
|`finallyStatements`|<span data-ttu-id="4f0d4-141">Facoltativa.</span><span class="sxs-lookup"><span data-stu-id="4f0d4-141">Optional.</span></span> <span data-ttu-id="4f0d4-142">Istruzioni che vengono eseguite dopo l'elaborazione di tutti gli altri errori.</span><span class="sxs-lookup"><span data-stu-id="4f0d4-142">Statement(s) that are executed after all other error processing has occurred.</span></span>|
|`End Try`|<span data-ttu-id="4f0d4-143">Termina la `Try...Catch...Finally` struttura.</span><span class="sxs-lookup"><span data-stu-id="4f0d4-143">Terminates the `Try...Catch...Finally` structure.</span></span>|

## <a name="remarks"></a><span data-ttu-id="4f0d4-144">Commenti</span><span class="sxs-lookup"><span data-stu-id="4f0d4-144">Remarks</span></span>

<span data-ttu-id="4f0d4-145">Se si prevede che una particolare eccezione possa verificarsi durante una particolare sezione di codice, inserire il codice in un `Try` blocco e usare un `Catch` blocco per mantenere il controllo e gestire l'eccezione, se si verifica.</span><span class="sxs-lookup"><span data-stu-id="4f0d4-145">If you expect that a particular exception might occur during a particular section of code, put the code in a `Try` block and use a `Catch` block to retain control and handle the exception if it occurs.</span></span>

<span data-ttu-id="4f0d4-146">Un' `Try…Catch` istruzione è costituita `Try` da un blocco seguito da una o più `Catch` clausole, che specificano i gestori per varie eccezioni.</span><span class="sxs-lookup"><span data-stu-id="4f0d4-146">A `Try…Catch` statement consists of a `Try` block followed by one or more `Catch` clauses, which specify handlers for various exceptions.</span></span> <span data-ttu-id="4f0d4-147">Quando viene generata un'eccezione in un `Try` blocco, Visual Basic cerca l' `Catch` istruzione che gestisce l'eccezione.</span><span class="sxs-lookup"><span data-stu-id="4f0d4-147">When an exception is thrown in a `Try` block, Visual Basic looks for the `Catch` statement that handles the exception.</span></span> <span data-ttu-id="4f0d4-148">Se `Catch` non viene trovata alcuna istruzione corrispondente, Visual Basic esamina il metodo che ha chiamato il metodo corrente e così via fino allo stack di chiamate.</span><span class="sxs-lookup"><span data-stu-id="4f0d4-148">If a matching `Catch` statement is not found, Visual Basic examines the method that called the current method, and so on up the call stack.</span></span> <span data-ttu-id="4f0d4-149">Se non `Catch` viene trovato alcun blocco, Visual Basic Visualizza un messaggio di eccezione non gestita per l'utente e interrompe l'esecuzione del programma.</span><span class="sxs-lookup"><span data-stu-id="4f0d4-149">If no `Catch` block is found, Visual Basic displays an unhandled exception message to the user and stops execution of the program.</span></span>

<span data-ttu-id="4f0d4-150">In un'istruzione è possibile utilizzare più di un' `Catch` istruzione `Try…Catch` .</span><span class="sxs-lookup"><span data-stu-id="4f0d4-150">You can use more than one `Catch` statement in a `Try…Catch` statement.</span></span> <span data-ttu-id="4f0d4-151">In tal caso, l'ordine delle `Catch` clausole è significativo perché vengono esaminate in ordine.</span><span class="sxs-lookup"><span data-stu-id="4f0d4-151">If you do this, the order of the `Catch` clauses is significant because they are examined in order.</span></span> <span data-ttu-id="4f0d4-152">Intercettare le eccezioni più specifiche prima di quelle meno specifiche.</span><span class="sxs-lookup"><span data-stu-id="4f0d4-152">Catch the more specific exceptions before the less specific ones.</span></span>

<span data-ttu-id="4f0d4-153">Le `Catch` condizioni dell'istruzione seguenti sono le meno specifiche e intercettano tutte le eccezioni che derivano dalla <xref:System.Exception> classe.</span><span class="sxs-lookup"><span data-stu-id="4f0d4-153">The following `Catch` statement conditions are the least specific, and will catch all exceptions that derive from the <xref:System.Exception> class.</span></span> <span data-ttu-id="4f0d4-154">In genere, è consigliabile usare una di queste varianti come ultimo `Catch` blocco nella `Try...Catch...Finally` struttura, dopo avere intercettato tutte le eccezioni specifiche previste.</span><span class="sxs-lookup"><span data-stu-id="4f0d4-154">You should ordinarily use one of these variations as the last `Catch` block in the `Try...Catch...Finally` structure, after catching all the specific exceptions you expect.</span></span> <span data-ttu-id="4f0d4-155">Il flusso di controllo non può mai raggiungere un `Catch` blocco che segue una di queste varianti.</span><span class="sxs-lookup"><span data-stu-id="4f0d4-155">Control flow can never reach a `Catch` block that follows either of these variations.</span></span>

- <span data-ttu-id="4f0d4-156">`type`È `Exception` , ad esempio:`Catch ex As Exception`</span><span class="sxs-lookup"><span data-stu-id="4f0d4-156">The `type` is `Exception`, for example: `Catch ex As Exception`</span></span>

- <span data-ttu-id="4f0d4-157">L'istruzione non ha alcuna `exception` variabile, ad esempio:`Catch`</span><span class="sxs-lookup"><span data-stu-id="4f0d4-157">The statement has no `exception` variable, for example: `Catch`</span></span>

<span data-ttu-id="4f0d4-158">Quando un' `Try…Catch…Finally` istruzione è annidata in un altro `Try` blocco, Visual Basic esamina prima ogni `Catch` istruzione nel blocco più interno `Try` .</span><span class="sxs-lookup"><span data-stu-id="4f0d4-158">When a `Try…Catch…Finally` statement is nested in another `Try` block, Visual Basic first examines each `Catch` statement in the innermost `Try` block.</span></span> <span data-ttu-id="4f0d4-159">Se non `Catch` viene trovata alcuna istruzione corrispondente, la ricerca procede alle `Catch` istruzioni del `Try…Catch…Finally` blocco esterno.</span><span class="sxs-lookup"><span data-stu-id="4f0d4-159">If no matching `Catch` statement is found, the search proceeds to the `Catch` statements of the outer `Try…Catch…Finally` block.</span></span>

<span data-ttu-id="4f0d4-160">Le variabili locali di un `Try` blocco non sono disponibili in un `Catch` blocco perché sono blocchi separati.</span><span class="sxs-lookup"><span data-stu-id="4f0d4-160">Local variables from a `Try` block are not available in a `Catch` block because they are separate blocks.</span></span> <span data-ttu-id="4f0d4-161">Se si desidera utilizzare una variabile in più di un blocco, dichiarare la variabile all'esterno della `Try...Catch...Finally` struttura.</span><span class="sxs-lookup"><span data-stu-id="4f0d4-161">If you want to use a variable in more than one block, declare the variable outside the `Try...Catch...Finally` structure.</span></span>

> [!TIP]
> <span data-ttu-id="4f0d4-162">L' `Try…Catch…Finally` istruzione è disponibile come frammento di codice IntelliSense.</span><span class="sxs-lookup"><span data-stu-id="4f0d4-162">The `Try…Catch…Finally` statement is available as an IntelliSense code snippet.</span></span> <span data-ttu-id="4f0d4-163">In Gestione frammenti di codice espandere modelli di **codice-if, for each, try catch, Property e così via**, quindi **gestione degli errori (eccezioni)**.</span><span class="sxs-lookup"><span data-stu-id="4f0d4-163">In the Code Snippets Manager, expand **Code Patterns - If, For Each, Try Catch, Property, etc**, and then **Error Handling (Exceptions)**.</span></span> <span data-ttu-id="4f0d4-164">Per altre informazioni, vedere [Code Snippets](/visualstudio/ide/code-snippets) (Frammenti di codice).</span><span class="sxs-lookup"><span data-stu-id="4f0d4-164">For more information, see [Code Snippets](/visualstudio/ide/code-snippets).</span></span>

## <a name="finally-block"></a><span data-ttu-id="4f0d4-165">Blocco finally</span><span class="sxs-lookup"><span data-stu-id="4f0d4-165">Finally block</span></span>

<span data-ttu-id="4f0d4-166">Se si dispone di una o più istruzioni che devono essere eseguite prima di uscire dalla `Try` struttura, utilizzare un `Finally` blocco.</span><span class="sxs-lookup"><span data-stu-id="4f0d4-166">If you have one or more statements that must run before you exit the `Try` structure, use a `Finally` block.</span></span> <span data-ttu-id="4f0d4-167">Il controllo passa al `Finally` blocco immediatamente prima che venga passato all'esterno della `Try…Catch` struttura.</span><span class="sxs-lookup"><span data-stu-id="4f0d4-167">Control passes to the `Finally` block just before it passes out of the `Try…Catch` structure.</span></span> <span data-ttu-id="4f0d4-168">Questo vale anche se si verifica un'eccezione in qualsiasi punto all'interno della `Try` struttura.</span><span class="sxs-lookup"><span data-stu-id="4f0d4-168">This is true even if an exception occurs anywhere inside the `Try` structure.</span></span>

<span data-ttu-id="4f0d4-169">Un `Finally` blocco è utile per l'esecuzione di codice che deve essere eseguito anche se si verifica un'eccezione.</span><span class="sxs-lookup"><span data-stu-id="4f0d4-169">A `Finally` block is useful for running any code that must execute even if there is an exception.</span></span> <span data-ttu-id="4f0d4-170">Il controllo viene passato al `Finally` blocco indipendentemente dal modo in cui il `Try...Catch` blocco viene chiuso.</span><span class="sxs-lookup"><span data-stu-id="4f0d4-170">Control is passed to the `Finally` block regardless of how the `Try...Catch` block exits.</span></span>

<span data-ttu-id="4f0d4-171">Il codice in un `Finally` blocco viene eseguito anche se il codice rileva un' `Return` istruzione in un `Try` blocco o `Catch` .</span><span class="sxs-lookup"><span data-stu-id="4f0d4-171">The code in a `Finally` block runs even if your code encounters a `Return` statement in a `Try` or `Catch` block.</span></span> <span data-ttu-id="4f0d4-172">Il controllo non passa da un `Try` `Catch` blocco o al blocco corrispondente `Finally` nei casi seguenti:</span><span class="sxs-lookup"><span data-stu-id="4f0d4-172">Control does not pass from a `Try` or `Catch` block to the corresponding `Finally` block in the following cases:</span></span>

- <span data-ttu-id="4f0d4-173">Nel blocco o viene rilevata un' [istruzione End](end-statement.md) `Try` `Catch` .</span><span class="sxs-lookup"><span data-stu-id="4f0d4-173">An [End Statement](end-statement.md) is encountered in the `Try` or `Catch` block.</span></span>

- <span data-ttu-id="4f0d4-174"><xref:System.StackOverflowException>Viene generata un'eccezione nel `Try` `Catch` blocco o.</span><span class="sxs-lookup"><span data-stu-id="4f0d4-174">A <xref:System.StackOverflowException> is thrown in the `Try` or `Catch` block.</span></span>

<span data-ttu-id="4f0d4-175">Non è possibile trasferire in modo esplicito l'esecuzione in un `Finally` blocco.</span><span class="sxs-lookup"><span data-stu-id="4f0d4-175">It is not valid to explicitly transfer execution into a `Finally` block.</span></span> <span data-ttu-id="4f0d4-176">Il trasferimento dell'esecuzione da un `Finally` blocco non è valido, ad eccezione di un'eccezione.</span><span class="sxs-lookup"><span data-stu-id="4f0d4-176">Transferring execution out of a `Finally` block is not valid, except through an exception.</span></span>

<span data-ttu-id="4f0d4-177">Se un' `Try` istruzione non contiene almeno un `Catch` blocco, deve contenere un `Finally` blocco.</span><span class="sxs-lookup"><span data-stu-id="4f0d4-177">If a `Try` statement does not contain at least one `Catch` block, it must contain a `Finally` block.</span></span>

> [!TIP]
> <span data-ttu-id="4f0d4-178">Se non è necessario intercettare eccezioni specifiche, l' `Using` istruzione si comporta come un `Try…Finally` blocco e garantisce l'eliminazione delle risorse, indipendentemente dalla modalità di uscita dal blocco.</span><span class="sxs-lookup"><span data-stu-id="4f0d4-178">If you do not have to catch specific exceptions, the `Using` statement behaves like a `Try…Finally` block, and guarantees disposal of the resources, regardless of how you exit the block.</span></span> <span data-ttu-id="4f0d4-179">Questo vale anche con un'eccezione non gestita.</span><span class="sxs-lookup"><span data-stu-id="4f0d4-179">This is true even with an unhandled exception.</span></span> <span data-ttu-id="4f0d4-180">Per ulteriori informazioni, vedere [istruzione using](using-statement.md).</span><span class="sxs-lookup"><span data-stu-id="4f0d4-180">For more information, see [Using Statement](using-statement.md).</span></span>

## <a name="exception-argument"></a><span data-ttu-id="4f0d4-181">Argomento Exception</span><span class="sxs-lookup"><span data-stu-id="4f0d4-181">Exception argument</span></span>

<span data-ttu-id="4f0d4-182">L' `Catch` `exception` argomento Block è un'istanza della <xref:System.Exception> classe o una classe che deriva dalla `Exception` classe.</span><span class="sxs-lookup"><span data-stu-id="4f0d4-182">The `Catch` block `exception` argument is an instance of the <xref:System.Exception> class or a class that derives from the `Exception` class.</span></span> <span data-ttu-id="4f0d4-183">L' `Exception` istanza della classe corrisponde all'errore che si è verificato nel `Try` blocco.</span><span class="sxs-lookup"><span data-stu-id="4f0d4-183">The `Exception` class instance corresponds to the error that occurred in the `Try` block.</span></span>

<span data-ttu-id="4f0d4-184">Le proprietà dell' `Exception` oggetto consentono di identificare la ragione e la posizione di un'eccezione.</span><span class="sxs-lookup"><span data-stu-id="4f0d4-184">The properties of the `Exception` object help to identify the cause and location of an exception.</span></span> <span data-ttu-id="4f0d4-185">Ad esempio, la <xref:System.Exception.StackTrace%2A> proprietà elenca i metodi chiamati che hanno generato l'eccezione, consentendo di individuare la posizione in cui si è verificato l'errore nel codice.</span><span class="sxs-lookup"><span data-stu-id="4f0d4-185">For example, the <xref:System.Exception.StackTrace%2A> property lists the called methods that led to the exception, helping you find where the error occurred in the code.</span></span> <span data-ttu-id="4f0d4-186"><xref:System.Exception.Message%2A>Restituisce un messaggio che descrive l'eccezione.</span><span class="sxs-lookup"><span data-stu-id="4f0d4-186"><xref:System.Exception.Message%2A> returns a message that describes the exception.</span></span> <span data-ttu-id="4f0d4-187"><xref:System.Exception.HelpLink%2A>Restituisce un collegamento a un file della Guida associato.</span><span class="sxs-lookup"><span data-stu-id="4f0d4-187"><xref:System.Exception.HelpLink%2A> returns a link to an associated Help file.</span></span> <span data-ttu-id="4f0d4-188"><xref:System.Exception.InnerException%2A>Restituisce l' `Exception` oggetto che ha causato l'eccezione corrente oppure restituisce `Nothing` se non è presente alcun oggetto originale `Exception` .</span><span class="sxs-lookup"><span data-stu-id="4f0d4-188"><xref:System.Exception.InnerException%2A> returns the `Exception` object that caused the current exception, or it returns `Nothing` if there is no original `Exception`.</span></span>

## <a name="considerations-when-using-a-trycatch-statement"></a><span data-ttu-id="4f0d4-189">Considerazioni sull'utilizzo di un try... Istruzione catch</span><span class="sxs-lookup"><span data-stu-id="4f0d4-189">Considerations when using a Try…Catch statement</span></span>

<span data-ttu-id="4f0d4-190">Utilizzare un' `Try…Catch` istruzione solo per segnalare l'occorrenza di eventi di programma insoliti o imprevisti.</span><span class="sxs-lookup"><span data-stu-id="4f0d4-190">Use a `Try…Catch` statement only to signal the occurrence of unusual or unanticipated program events.</span></span> <span data-ttu-id="4f0d4-191">Di seguito sono riportati alcuni motivi:</span><span class="sxs-lookup"><span data-stu-id="4f0d4-191">Reasons for this include the following:</span></span>

- <span data-ttu-id="4f0d4-192">Il rilevamento delle eccezioni in fase di esecuzione comporta un sovraccarico aggiuntivo ed è probabilmente più lento rispetto al controllo preliminare per evitare eccezioni.</span><span class="sxs-lookup"><span data-stu-id="4f0d4-192">Catching exceptions at runtime creates additional overhead, and is likely to be slower than pre-checking to avoid exceptions.</span></span>

- <span data-ttu-id="4f0d4-193">Se un `Catch` blocco non viene gestito correttamente, l'eccezione potrebbe non essere segnalata correttamente agli utenti.</span><span class="sxs-lookup"><span data-stu-id="4f0d4-193">If a `Catch` block is not handled correctly, the exception might not be reported correctly to users.</span></span>

- <span data-ttu-id="4f0d4-194">La gestione delle eccezioni rende un programma più complesso.</span><span class="sxs-lookup"><span data-stu-id="4f0d4-194">Exception handling makes a program more complex.</span></span>

<span data-ttu-id="4f0d4-195">Non è sempre necessaria un' `Try…Catch` istruzione per verificare la presenza di una condizione che potrebbe verificarsi.</span><span class="sxs-lookup"><span data-stu-id="4f0d4-195">You do not always need a `Try…Catch` statement to check for a condition that is likely to occur.</span></span> <span data-ttu-id="4f0d4-196">Nell'esempio seguente viene verificata l'esistenza di un file prima di tentare di aprirlo.</span><span class="sxs-lookup"><span data-stu-id="4f0d4-196">The following example checks whether a file exists before trying to open it.</span></span> <span data-ttu-id="4f0d4-197">In questo modo si riduce la necessità di intercettare un'eccezione generata dal <xref:System.IO.File.OpenText%2A> metodo.</span><span class="sxs-lookup"><span data-stu-id="4f0d4-197">This reduces the need for catching an exception thrown by the <xref:System.IO.File.OpenText%2A> method.</span></span>

[!code-vb[VbVbalrStatements#94](~/samples/snippets/visualbasic/VS_Snippets_VBCSharp/VbVbalrStatements/VB/Class1.vb#94)]

<span data-ttu-id="4f0d4-198">Verificare che il codice in `Catch` blocchi possa segnalare correttamente le eccezioni agli utenti, sia tramite la registrazione thread-safe che i messaggi appropriati.</span><span class="sxs-lookup"><span data-stu-id="4f0d4-198">Ensure that code in `Catch` blocks can properly report exceptions to users, whether through thread-safe logging or appropriate messages.</span></span> <span data-ttu-id="4f0d4-199">In caso contrario, le eccezioni potrebbero rimanere sconosciute.</span><span class="sxs-lookup"><span data-stu-id="4f0d4-199">Otherwise, exceptions might remain unknown.</span></span>

## <a name="async-methods"></a><span data-ttu-id="4f0d4-200">Metodi asincroni</span><span class="sxs-lookup"><span data-stu-id="4f0d4-200">Async methods</span></span>

<span data-ttu-id="4f0d4-201">Se si contrassegna un metodo con il modificatore [Async](../modifiers/async.md) , è possibile usare l'operatore [await](../operators/await-operator.md) nel metodo.</span><span class="sxs-lookup"><span data-stu-id="4f0d4-201">If you mark a method with the [Async](../modifiers/async.md) modifier, you can use the [Await](../operators/await-operator.md) operator in the method.</span></span> <span data-ttu-id="4f0d4-202">Un'istruzione con l' `Await` operatore sospende l'esecuzione del metodo fino al completamento dell'attività attesa.</span><span class="sxs-lookup"><span data-stu-id="4f0d4-202">A statement with the `Await` operator suspends execution of the method until the awaited task completes.</span></span> <span data-ttu-id="4f0d4-203">L'attività rappresenta il lavoro attualmente in fase di esecuzione.</span><span class="sxs-lookup"><span data-stu-id="4f0d4-203">The task represents ongoing work.</span></span> <span data-ttu-id="4f0d4-204">Quando l'attività associata all' `Await` operatore termina, l'esecuzione riprende nello stesso metodo.</span><span class="sxs-lookup"><span data-stu-id="4f0d4-204">When the task that's associated with the `Await` operator finishes, execution resumes in the same method.</span></span> <span data-ttu-id="4f0d4-205">Per altre informazioni, vedere [flusso di controllo in programmi asincroni](../../programming-guide/concepts/async/control-flow-in-async-programs.md).</span><span class="sxs-lookup"><span data-stu-id="4f0d4-205">For more information, see [Control Flow in Async Programs](../../programming-guide/concepts/async/control-flow-in-async-programs.md).</span></span>

<span data-ttu-id="4f0d4-206">Un'attività restituita da un metodo asincrono può terminare con uno stato di errore, a indicare che è stata completata a causa di un'eccezione non gestita.</span><span class="sxs-lookup"><span data-stu-id="4f0d4-206">A task returned by an Async method may end in a faulted state, indicating that it completed due to an unhandled exception.</span></span> <span data-ttu-id="4f0d4-207">Un'attività può inoltre terminare con uno stato annullato, il che comporta la generazione `OperationCanceledException` di un'eccezione dall'espressione await.</span><span class="sxs-lookup"><span data-stu-id="4f0d4-207">A task may also end in a canceled state, which results in an `OperationCanceledException` being thrown out of the await expression.</span></span> <span data-ttu-id="4f0d4-208">Per intercettare entrambi i tipi di eccezione, inserire l' `Await` espressione associata all'attività in un `Try` blocco e intercettare l'eccezione nel `Catch` blocco.</span><span class="sxs-lookup"><span data-stu-id="4f0d4-208">To catch either type of exception, place the `Await` expression that's associated with the task in a `Try` block, and catch the exception in the `Catch` block.</span></span> <span data-ttu-id="4f0d4-209">Un esempio è disponibile più avanti in questo argomento.</span><span class="sxs-lookup"><span data-stu-id="4f0d4-209">An example is provided later in this topic.</span></span>

<span data-ttu-id="4f0d4-210">Un'attività può essere in uno stato di errore perché più eccezioni erano responsabili dell'errore.</span><span class="sxs-lookup"><span data-stu-id="4f0d4-210">A task can be in a faulted state because multiple exceptions were responsible for its faulting.</span></span> <span data-ttu-id="4f0d4-211">Ad esempio, l'attività può essere il risultato di una chiamata a <xref:System.Threading.Tasks.Task.WhenAll%2A?displayProperty=nameWithType>.</span><span class="sxs-lookup"><span data-stu-id="4f0d4-211">For example, the task might be the result of a call to <xref:System.Threading.Tasks.Task.WhenAll%2A?displayProperty=nameWithType>.</span></span> <span data-ttu-id="4f0d4-212">Quando si attende tale attività, l'eccezione rilevata è solo una delle eccezioni e non è possibile prevedere quale eccezione verrà rilevata.</span><span class="sxs-lookup"><span data-stu-id="4f0d4-212">When you await such a task, the caught exception is only one of the exceptions, and you can't predict which exception will be caught.</span></span> <span data-ttu-id="4f0d4-213">Un esempio è disponibile più avanti in questo argomento.</span><span class="sxs-lookup"><span data-stu-id="4f0d4-213">An example is provided later in this topic.</span></span>

<span data-ttu-id="4f0d4-214">Un' `Await` espressione non può trovarsi all'interno di un `Catch` blocco o di un `Finally` blocco.</span><span class="sxs-lookup"><span data-stu-id="4f0d4-214">An `Await` expression can't be inside a `Catch` block or `Finally` block.</span></span>

## <a name="iterators"></a><span data-ttu-id="4f0d4-215">Iterators</span><span class="sxs-lookup"><span data-stu-id="4f0d4-215">Iterators</span></span>

<span data-ttu-id="4f0d4-216">Una funzione o una funzione di accesso iteratore `Get` esegue un'iterazione personalizzata su una raccolta.</span><span class="sxs-lookup"><span data-stu-id="4f0d4-216">An iterator function or `Get` accessor performs a custom iteration over a collection.</span></span> <span data-ttu-id="4f0d4-217">Un iteratore usa un'istruzione [yield](yield-statement.md) per restituire ogni elemento della raccolta uno alla volta.</span><span class="sxs-lookup"><span data-stu-id="4f0d4-217">An iterator uses a [Yield](yield-statement.md) statement to return each element of the collection one at a time.</span></span> <span data-ttu-id="4f0d4-218">Si chiama una funzione iteratore usando un [per ogni... Istruzione successiva](for-each-next-statement.md).</span><span class="sxs-lookup"><span data-stu-id="4f0d4-218">You call an iterator function by using a [For Each...Next Statement](for-each-next-statement.md).</span></span>

<span data-ttu-id="4f0d4-219">Un' `Yield` istruzione può trovarsi all'interno di un `Try` blocco.</span><span class="sxs-lookup"><span data-stu-id="4f0d4-219">A `Yield` statement can be inside a `Try` block.</span></span> <span data-ttu-id="4f0d4-220">Un `Try` blocco che contiene un' `Yield` istruzione può contenere `Catch` blocchi e può avere un `Finally` blocco.</span><span class="sxs-lookup"><span data-stu-id="4f0d4-220">A `Try` block that contains a `Yield` statement can have `Catch` blocks, and can have a `Finally` block.</span></span> <span data-ttu-id="4f0d4-221">Per un esempio, vedere la sezione "blocchi try in Visual Basic" degli [iteratori](../../programming-guide/concepts/iterators.md) .</span><span class="sxs-lookup"><span data-stu-id="4f0d4-221">See the "Try Blocks in Visual Basic" section of [Iterators](../../programming-guide/concepts/iterators.md) for an example.</span></span>

<span data-ttu-id="4f0d4-222">Un' `Yield` istruzione non può trovarsi all'interno di un `Catch` blocco o di un `Finally` blocco.</span><span class="sxs-lookup"><span data-stu-id="4f0d4-222">A `Yield` statement cannot be inside a `Catch` block or a `Finally` block.</span></span>

<span data-ttu-id="4f0d4-223">Se il `For Each` corpo (all'esterno della funzione iteratore) genera un'eccezione, un `Catch` blocco nella funzione iteratore non viene eseguito, ma `Finally` viene eseguito un blocco nella funzione iteratore.</span><span class="sxs-lookup"><span data-stu-id="4f0d4-223">If the `For Each` body (outside of the iterator function) throws an exception, a `Catch` block in the iterator function is not executed, but a `Finally` block in the iterator function is executed.</span></span> <span data-ttu-id="4f0d4-224">Un `Catch` blocco all'interno di una funzione iteratore intercetta solo le eccezioni che si verificano all'interno della funzione iteratore.</span><span class="sxs-lookup"><span data-stu-id="4f0d4-224">A `Catch` block inside an iterator function catches only exceptions that occur inside the iterator function.</span></span>

## <a name="partial-trust-situations"></a><span data-ttu-id="4f0d4-225">Situazioni di attendibilità parziale</span><span class="sxs-lookup"><span data-stu-id="4f0d4-225">Partial-trust situations</span></span>

<span data-ttu-id="4f0d4-226">In situazioni di attendibilità parziale, ad esempio un'applicazione ospitata in una condivisione di rete, non `Try...Catch...Finally` rileva le eccezioni di sicurezza che si verificano prima che venga richiamato il metodo che contiene la chiamata.</span><span class="sxs-lookup"><span data-stu-id="4f0d4-226">In partial-trust situations, such as an application hosted on a network share, `Try...Catch...Finally` does not catch security exceptions that occur before the method that contains the call is invoked.</span></span> <span data-ttu-id="4f0d4-227">Nell'esempio seguente, quando lo si inserisce in una condivisione server e si esegue da questa posizione, viene generato l'errore "System. Security. SecurityException: request failed".</span><span class="sxs-lookup"><span data-stu-id="4f0d4-227">The following example, when you put it on a server share and run from there, produces the error "System.Security.SecurityException: Request Failed."</span></span> <span data-ttu-id="4f0d4-228">Per ulteriori informazioni sulle eccezioni di sicurezza, vedere la <xref:System.Security.SecurityException> classe.</span><span class="sxs-lookup"><span data-stu-id="4f0d4-228">For more information about security exceptions, see the <xref:System.Security.SecurityException> class.</span></span>

[!code-vb[VbVbalrStatements#85](~/samples/snippets/visualbasic/VS_Snippets_VBCSharp/VbVbalrStatements/VB/Class1.vb#85)]

<span data-ttu-id="4f0d4-229">In una situazione di attendibilità parziale, è necessario inserire l' `Process.Start` istruzione in un oggetto separato `Sub` .</span><span class="sxs-lookup"><span data-stu-id="4f0d4-229">In such a partial-trust situation, you have to put the `Process.Start` statement in a separate `Sub`.</span></span> <span data-ttu-id="4f0d4-230">La chiamata iniziale a `Sub` avrà esito negativo.</span><span class="sxs-lookup"><span data-stu-id="4f0d4-230">The initial call to the `Sub` will fail.</span></span> <span data-ttu-id="4f0d4-231">In questo modo, è possibile `Try...Catch` intercettarlo prima `Sub` che venga avviato l'oggetto che contiene `Process.Start` e l'eccezione di sicurezza prodotta.</span><span class="sxs-lookup"><span data-stu-id="4f0d4-231">This enables `Try...Catch` to catch it before the `Sub` that contains `Process.Start` is started and the security exception produced.</span></span>

## <a name="examples"></a><span data-ttu-id="4f0d4-232">Esempi</span><span class="sxs-lookup"><span data-stu-id="4f0d4-232">Examples</span></span>

### <a name="the-structure-of-trycatchfinally"></a><span data-ttu-id="4f0d4-233">Struttura di try... Rileva... Infine</span><span class="sxs-lookup"><span data-stu-id="4f0d4-233">The structure of Try...Catch...Finally</span></span>

<span data-ttu-id="4f0d4-234">Nell'esempio seguente viene illustrata la struttura dell' `Try...Catch...Finally` istruzione.</span><span class="sxs-lookup"><span data-stu-id="4f0d4-234">The following example illustrates the structure of the `Try...Catch...Finally` statement.</span></span>

[!code-vb[VbVbalrStatements#86](~/samples/snippets/visualbasic/VS_Snippets_VBCSharp/VbVbalrStatements/VB/Class1.vb#86)]  

### <a name="exception-in-a-method-called-from-a-try-block"></a><span data-ttu-id="4f0d4-235">Eccezione in un metodo chiamato da un blocco try</span><span class="sxs-lookup"><span data-stu-id="4f0d4-235">Exception in a method called from a Try block</span></span>

<span data-ttu-id="4f0d4-236">Nell'esempio seguente, il `CreateException` metodo genera un'eccezione `NullReferenceException` .</span><span class="sxs-lookup"><span data-stu-id="4f0d4-236">In the following example, the `CreateException` method throws a `NullReferenceException`.</span></span> <span data-ttu-id="4f0d4-237">Il codice che genera l'eccezione non si trova in un `Try` blocco.</span><span class="sxs-lookup"><span data-stu-id="4f0d4-237">The code that generates the exception is not in a `Try` block.</span></span> <span data-ttu-id="4f0d4-238">Pertanto, il `CreateException` metodo non gestisce l'eccezione.</span><span class="sxs-lookup"><span data-stu-id="4f0d4-238">Therefore, the `CreateException` method does not handle the exception.</span></span> <span data-ttu-id="4f0d4-239">Il `RunSample` metodo gestisce l'eccezione perché la chiamata al `CreateException` metodo si trova in un `Try` blocco.</span><span class="sxs-lookup"><span data-stu-id="4f0d4-239">The `RunSample` method does handle the exception because the call to the `CreateException` method is in a `Try` block.</span></span>

<span data-ttu-id="4f0d4-240">Nell'esempio sono incluse `Catch` istruzioni per diversi tipi di eccezioni, ordinate dal più specifico al più generale.</span><span class="sxs-lookup"><span data-stu-id="4f0d4-240">The example includes `Catch` statements for several types of exceptions, ordered from the most specific to the most general.</span></span>

[!code-vb[VbVbalrStatements#91](~/samples/snippets/visualbasic/VS_Snippets_VBCSharp/VbVbalrStatements/VB/Class1.vb#91)]

### <a name="the-catch-when-statement"></a><span data-ttu-id="4f0d4-241">Istruzione catch when</span><span class="sxs-lookup"><span data-stu-id="4f0d4-241">The Catch When statement</span></span>

<span data-ttu-id="4f0d4-242">Nell'esempio seguente viene illustrato come utilizzare un' `Catch When` istruzione per filtrare in un'espressione condizionale.</span><span class="sxs-lookup"><span data-stu-id="4f0d4-242">The following example shows how to use a `Catch When` statement to filter on a conditional expression.</span></span> <span data-ttu-id="4f0d4-243">Se l'espressione condizionale restituisce `True` , viene eseguito il codice nel `Catch` blocco.</span><span class="sxs-lookup"><span data-stu-id="4f0d4-243">If the conditional expression evaluates to `True`, the code in the `Catch` block runs.</span></span>

[!code-vb[VbVbalrStatements#92](~/samples/snippets/visualbasic/VS_Snippets_VBCSharp/VbVbalrStatements/VB/Class1.vb#92)]

### <a name="nested-try-statements"></a><span data-ttu-id="4f0d4-244">Istruzioni try nidificate</span><span class="sxs-lookup"><span data-stu-id="4f0d4-244">Nested Try statements</span></span>

<span data-ttu-id="4f0d4-245">Nell'esempio seguente è `Try…Catch` presente un'istruzione contenuta in un `Try` blocco.</span><span class="sxs-lookup"><span data-stu-id="4f0d4-245">The following example has a `Try…Catch` statement that is contained in a `Try` block.</span></span> <span data-ttu-id="4f0d4-246">Il `Catch` blocco interno genera un'eccezione la cui `InnerException` proprietà è impostata sull'eccezione originale.</span><span class="sxs-lookup"><span data-stu-id="4f0d4-246">The inner `Catch` block throws an exception that has its `InnerException` property set to the original exception.</span></span> <span data-ttu-id="4f0d4-247">Il `Catch` blocco esterno segnala la propria eccezione e l'eccezione interna.</span><span class="sxs-lookup"><span data-stu-id="4f0d4-247">The outer `Catch` block reports its own exception and the inner exception.</span></span>

[!code-vb[VbVbalrStatements#93](~/samples/snippets/visualbasic/VS_Snippets_VBCSharp/VbVbalrStatements/VB/Class1.vb#93)]

### <a name="exception-handling-for-async-methods"></a><span data-ttu-id="4f0d4-248">Gestione delle eccezioni per i metodi asincroni</span><span class="sxs-lookup"><span data-stu-id="4f0d4-248">Exception handling for async methods</span></span>

<span data-ttu-id="4f0d4-249">L'esempio seguente illustra la gestione delle eccezioni per i metodi asincroni.</span><span class="sxs-lookup"><span data-stu-id="4f0d4-249">The following example illustrates exception handling for async methods.</span></span> <span data-ttu-id="4f0d4-250">Per intercettare un'eccezione che si applica a un'attività asincrona, l' `Await` espressione si trova in un `Try` blocco del chiamante e l'eccezione viene rilevata nel `Catch` blocco.</span><span class="sxs-lookup"><span data-stu-id="4f0d4-250">To catch an exception that applies to an async task, the `Await` expression is in a `Try` block of the caller, and the exception is caught in the `Catch` block.</span></span>

<span data-ttu-id="4f0d4-251">Rimuovere il commento dalla riga `Throw New Exception` nell'esempio per illustrare la gestione delle eccezioni.</span><span class="sxs-lookup"><span data-stu-id="4f0d4-251">Uncomment the `Throw New Exception` line in the example to demonstrate exception handling.</span></span> <span data-ttu-id="4f0d4-252">L'eccezione viene rilevata nel `Catch` blocco, la proprietà dell'attività `IsFaulted` viene impostata su `True` e la proprietà dell'attività `Exception.InnerException` viene impostata sull'eccezione.</span><span class="sxs-lookup"><span data-stu-id="4f0d4-252">The exception is caught in the `Catch` block, the task's `IsFaulted` property is set to `True`, and the task's `Exception.InnerException` property is set to the exception.</span></span>

<span data-ttu-id="4f0d4-253">Rimuovere il commento dalla riga `Throw New OperationCancelledException` per illustrare cosa accade quando si annulla un processo asincrono.</span><span class="sxs-lookup"><span data-stu-id="4f0d4-253">Uncomment the `Throw New OperationCancelledException` line to demonstrate what happens when you cancel an asynchronous process.</span></span> <span data-ttu-id="4f0d4-254">L'eccezione viene rilevata nel `Catch` blocco e la proprietà dell'attività `IsCanceled` viene impostata su `True` .</span><span class="sxs-lookup"><span data-stu-id="4f0d4-254">The exception is caught in the `Catch` block, and the task's `IsCanceled` property is set to `True`.</span></span> <span data-ttu-id="4f0d4-255">Tuttavia, in alcune condizioni che non si applicano a questo esempio, `IsFaulted` è impostato su `True` e `IsCanceled` è impostato su `False` .</span><span class="sxs-lookup"><span data-stu-id="4f0d4-255">However, under some conditions that don't apply to this example, `IsFaulted` is set to `True` and `IsCanceled` is set to `False`.</span></span>

[!code-vb[csAsyncExceptions#1](~/samples/snippets/visualbasic/VS_Snippets_VBCSharp/csasyncexceptions/vb/class1.vb#1)]

### <a name="handling-multiple-exceptions-in-async-methods"></a><span data-ttu-id="4f0d4-256">Gestione di più eccezioni nei metodi asincroni</span><span class="sxs-lookup"><span data-stu-id="4f0d4-256">Handling multiple exceptions in async methods</span></span>

<span data-ttu-id="4f0d4-257">Il seguente esempio illustra la gestione delle eccezioni dove più attività possono restituire più eccezioni.</span><span class="sxs-lookup"><span data-stu-id="4f0d4-257">The following example illustrates exception handling where multiple tasks can result in multiple exceptions.</span></span> <span data-ttu-id="4f0d4-258">Il `Try` blocco include l' `Await` espressione per l'attività <xref:System.Threading.Tasks.Task.WhenAll%2A?displayProperty=nameWithType> restituita.</span><span class="sxs-lookup"><span data-stu-id="4f0d4-258">The `Try` block has the `Await` expression for the task that <xref:System.Threading.Tasks.Task.WhenAll%2A?displayProperty=nameWithType> returned.</span></span> <span data-ttu-id="4f0d4-259">L'attività viene completata quando vengono completate le tre attività a cui <xref:System.Threading.Tasks.Task.WhenAll%2A?displayProperty=nameWithType> viene applicato.</span><span class="sxs-lookup"><span data-stu-id="4f0d4-259">The task is complete when the three tasks to which <xref:System.Threading.Tasks.Task.WhenAll%2A?displayProperty=nameWithType> is applied are complete.</span></span>

<span data-ttu-id="4f0d4-260">Ognuna delle tre attività genera un'eccezione.</span><span class="sxs-lookup"><span data-stu-id="4f0d4-260">Each of the three tasks causes an exception.</span></span> <span data-ttu-id="4f0d4-261">Il `Catch` blocco scorre le eccezioni presenti nella `Exception.InnerExceptions` proprietà dell'attività `Task.WhenAll` restituita.</span><span class="sxs-lookup"><span data-stu-id="4f0d4-261">The `Catch` block iterates through the exceptions, which are found in the `Exception.InnerExceptions` property of the task that `Task.WhenAll` returned.</span></span>

[!code-vb[csAsyncExceptions#3](~/samples/snippets/visualbasic/VS_Snippets_VBCSharp/csasyncexceptions/vb/class1.vb#3)]

## <a name="see-also"></a><span data-ttu-id="4f0d4-262">Vedere anche</span><span class="sxs-lookup"><span data-stu-id="4f0d4-262">See also</span></span>

- <xref:Microsoft.VisualBasic.Information.Err%2A>
- <xref:System.Exception>
- [<span data-ttu-id="4f0d4-263">Istruzione Exit</span><span class="sxs-lookup"><span data-stu-id="4f0d4-263">Exit Statement</span></span>](exit-statement.md)
- [<span data-ttu-id="4f0d4-264">Istruzione On Error</span><span class="sxs-lookup"><span data-stu-id="4f0d4-264">On Error Statement</span></span>](on-error-statement.md)
- [<span data-ttu-id="4f0d4-265">Procedure consigliate per l'uso dei frammenti di codice</span><span class="sxs-lookup"><span data-stu-id="4f0d4-265">Best Practices for Using Code Snippets</span></span>](/visualstudio/ide/best-practices-for-using-code-snippets)
- [<span data-ttu-id="4f0d4-266">Gestione delle eccezioni</span><span class="sxs-lookup"><span data-stu-id="4f0d4-266">Exception Handling</span></span>](../../../standard/parallel-programming/exception-handling-task-parallel-library.md)
- [<span data-ttu-id="4f0d4-267">Istruzione throw</span><span class="sxs-lookup"><span data-stu-id="4f0d4-267">Throw Statement</span></span>](throw-statement.md)
