---
title: L'istruzione 'Throw' non può omettere l'operando all'esterno di un'istruzione 'Catch' o all'interno di un'istruzione 'Finally'
ms.date: 07/20/2015
f1_keywords:
- vbc30666
- bc30666
helpviewer_keywords:
- BC30666
ms.assetid: a208a6ea-0e36-4bf1-8984-4de1a0e38a2a
ms.openlocfilehash: c4ab115b01e78c245cbd9f564b50573d6e30c5e7
ms.sourcegitcommit: f8c270376ed905f6a8896ce0fe25b4f4b38ff498
ms.translationtype: MT
ms.contentlocale: it-IT
ms.lasthandoff: 06/04/2020
ms.locfileid: "84414933"
---
# <a name="throw-statement-cannot-omit-operand-outside-a-catch-statement-or-inside-a-finally-statement"></a>L'istruzione 'Throw' non può omettere l'operando all'esterno di un'istruzione 'Catch' o all'interno di un'istruzione 'Finally'
Le istruzioni`Throw` di fuori dell'istruzione `Catch` devono fornire il nome di un oggetto eccezione.  
  
 **ID errore:** BC30666  
  
## <a name="to-correct-this-error"></a>Per correggere l'errore  
  
1. Specificare il nome di un oggetto eccezione derivato da `System.Exception`.  
  
2. Ristrutturare il codice in modo che l'istruzione `Throw` si trovi in un blocco `Catch` .  
  
## <a name="see-also"></a>Vedere anche

- [Istruzione throw](../language-reference/statements/throw-statement.md)
- [Istruzione Try...Catch...Finally](../language-reference/statements/try-catch-finally-statement.md)
- <xref:System.Exception?displayProperty=nameWithType>
- [Gestione e generazione di eccezioni in .NET](../../standard/exceptions/index.md)
